Traceback (most recent call last):
  File "/home/max/Documents/papers/ml-map/.venv/lib/python3.10/site-packages/jupyter_cache/executors/utils.py", line 58, in single_nb_execution
    executenb(
  File "/home/max/Documents/papers/ml-map/.venv/lib/python3.10/site-packages/nbclient/client.py", line 1314, in execute
    return NotebookClient(nb=nb, resources=resources, km=km, **kwargs).execute()
  File "/home/max/Documents/papers/ml-map/.venv/lib/python3.10/site-packages/jupyter_core/utils/__init__.py", line 173, in wrapped
    return loop.run_until_complete(inner)
  File "/usr/lib/python3.10/asyncio/base_events.py", line 649, in run_until_complete
    return future.result()
  File "/home/max/Documents/papers/ml-map/.venv/lib/python3.10/site-packages/nbclient/client.py", line 709, in async_execute
    await self.async_execute_cell(
  File "/home/max/Documents/papers/ml-map/.venv/lib/python3.10/site-packages/nbclient/client.py", line 1062, in async_execute_cell
    await self._check_raise_for_error(cell, cell_index, exec_reply)
  File "/home/max/Documents/papers/ml-map/.venv/lib/python3.10/site-packages/nbclient/client.py", line 918, in _check_raise_for_error
    raise CellExecutionError.from_cell_and_msg(cell, exec_reply_content)
nbclient.exceptions.CellExecutionError: An error occurred while executing the following cell:
------------------
labels = pd.read_feather('data/labels.feather')
print(labels.shape)
labels.head()
------------------


[0;31m---------------------------------------------------------------------------[0m
[0;31mNameError[0m                                 Traceback (most recent call last)
Cell [0;32mIn[2], line 1[0m
[0;32m----> 1[0m labels [38;5;241m=[39m [43mpd[49m[38;5;241m.[39mread_feather([38;5;124m'[39m[38;5;124mdata/labels.feather[39m[38;5;124m'[39m)
[1;32m      2[0m [38;5;28mprint[39m(labels[38;5;241m.[39mshape)
[1;32m      3[0m labels[38;5;241m.[39mhead()

[0;31mNameError[0m: name 'pd' is not defined

