Traceback (most recent call last):
  File "/home/max/Documents/papers/ml-map/.venv/lib/python3.10/site-packages/jupyter_cache/executors/utils.py", line 58, in single_nb_execution
    executenb(
  File "/home/max/Documents/papers/ml-map/.venv/lib/python3.10/site-packages/nbclient/client.py", line 1314, in execute
    return NotebookClient(nb=nb, resources=resources, km=km, **kwargs).execute()
  File "/home/max/Documents/papers/ml-map/.venv/lib/python3.10/site-packages/jupyter_core/utils/__init__.py", line 173, in wrapped
    return loop.run_until_complete(inner)
  File "/usr/lib/python3.10/asyncio/base_events.py", line 649, in run_until_complete
    return future.result()
  File "/home/max/Documents/papers/ml-map/.venv/lib/python3.10/site-packages/nbclient/client.py", line 709, in async_execute
    await self.async_execute_cell(
  File "/home/max/Documents/papers/ml-map/.venv/lib/python3.10/site-packages/nbclient/client.py", line 1062, in async_execute_cell
    await self._check_raise_for_error(cell, cell_index, exec_reply)
  File "/home/max/Documents/papers/ml-map/.venv/lib/python3.10/site-packages/nbclient/client.py", line 918, in _check_raise_for_error
    raise CellExecutionError.from_cell_and_msg(cell, exec_reply_content)
nbclient.exceptions.CellExecutionError: An error occurred while executing the following cell:
------------------
from datasets import Dataset
import pandas as pd
import re
from sklearn.model_selection import train_test_split
from mlmap import hf_tokenize_data, CustomTrainer
df = pd.read_feather('data/labels.feather').sample(128, random_state=2023).reset_index(drop=True)
df['text'] = df['title'] + ' ' + df['abstract']
y_prefix = 'INCLUDE'
targets = [x for x in df.columns if re.match(f'^{y_prefix}',x)]
if len(targets)==1:
    df['labels'] = df[targets[0]]
    binary=True
else:
    df['labels'] = df[targets]
    binary=False

model_name = 'distilroberta-base'
dataset = hf_tokenize_data(df, model_name)
train_idx, test_idx = train_test_split(df.index)
train_data = dataset.select(train_idx)
test_data = dataset.select(test_idx)
------------------

----- stderr -----
/home/max/Documents/papers/ml-map/.venv/lib/python3.10/site-packages/tqdm/auto.py:21: TqdmWarning: IProgress not found. Please update jupyter and ipywidgets. See https://ipywidgets.readthedocs.io/en/stable/user_install.html
  from .autonotebook import tqdm as notebook_tqdm
------------------

[0;31m---------------------------------------------------------------------------[0m
[0;31mModuleNotFoundError[0m                       Traceback (most recent call last)
Cell [0;32mIn[5], line 4[0m
[1;32m      2[0m [38;5;28;01mimport[39;00m [38;5;21;01mpandas[39;00m [38;5;28;01mas[39;00m [38;5;21;01mpd[39;00m
[1;32m      3[0m [38;5;28;01mimport[39;00m [38;5;21;01mre[39;00m
[0;32m----> 4[0m [38;5;28;01mfrom[39;00m [38;5;21;01msklearn[39;00m[38;5;21;01m.[39;00m[38;5;21;01mmodel_selection[39;00m [38;5;28;01mimport[39;00m train_test_split
[1;32m      5[0m [38;5;28;01mfrom[39;00m [38;5;21;01mmlmap[39;00m [38;5;28;01mimport[39;00m hf_tokenize_data, CustomTrainer
[1;32m      6[0m df [38;5;241m=[39m pd[38;5;241m.[39mread_feather([38;5;124m'[39m[38;5;124mdata/labels.feather[39m[38;5;124m'[39m)[38;5;241m.[39msample([38;5;241m128[39m, random_state[38;5;241m=[39m[38;5;241m2023[39m)[38;5;241m.[39mreset_index(drop[38;5;241m=[39m[38;5;28;01mTrue[39;00m)

[0;31mModuleNotFoundError[0m: No module named 'sklearn'

