Traceback (most recent call last):
  File "/home/galm/Documents/ml-map/.venv/lib/python3.11/site-packages/jupyter_cache/executors/utils.py", line 58, in single_nb_execution
    executenb(
  File "/home/galm/Documents/ml-map/.venv/lib/python3.11/site-packages/nbclient/client.py", line 1314, in execute
    return NotebookClient(nb=nb, resources=resources, km=km, **kwargs).execute()
           ^^^^^^^^^^^^^^^^^^^^^^^^^^^^^^^^^^^^^^^^^^^^^^^^^^^^^^^^^^^^^^^^^^^^^
  File "/home/galm/Documents/ml-map/.venv/lib/python3.11/site-packages/jupyter_core/utils/__init__.py", line 173, in wrapped
    return loop.run_until_complete(inner)
           ^^^^^^^^^^^^^^^^^^^^^^^^^^^^^^
  File "/usr/lib/python3.11/asyncio/base_events.py", line 653, in run_until_complete
    return future.result()
           ^^^^^^^^^^^^^^^
  File "/home/galm/Documents/ml-map/.venv/lib/python3.11/site-packages/nbclient/client.py", line 709, in async_execute
    await self.async_execute_cell(
  File "/home/galm/Documents/ml-map/.venv/lib/python3.11/site-packages/nbclient/client.py", line 1062, in async_execute_cell
    await self._check_raise_for_error(cell, cell_index, exec_reply)
  File "/home/galm/Documents/ml-map/.venv/lib/python3.11/site-packages/nbclient/client.py", line 918, in _check_raise_for_error
    raise CellExecutionError.from_cell_and_msg(cell, exec_reply_content)
nbclient.exceptions.CellExecutionError: An error occurred while executing the following cell:
------------------
df = df[df['INCLUDE']>=0.5]
df = df.dropna(['title','abstract'])

print(df.shape)

df = get_categories(model_name, '4 -', seen_df, df)
df = get_categories(model_name, '8 -', seen_df, df)

df.to_feather('data/final_dataset.feather')

df.head()
------------------


[0;31m---------------------------------------------------------------------------[0m
[0;31mTypeError[0m                                 Traceback (most recent call last)
Cell [0;32mIn[8], line 2[0m
[1;32m      1[0m df [38;5;241m=[39m df[df[[38;5;124m'[39m[38;5;124mINCLUDE[39m[38;5;124m'[39m][38;5;241m>[39m[38;5;241m=[39m[38;5;241m0.5[39m]
[0;32m----> 2[0m df [38;5;241m=[39m [43mdf[49m[38;5;241;43m.[39;49m[43mdropna[49m[43m([49m[43m[[49m[38;5;124;43m'[39;49m[38;5;124;43mtitle[39;49m[38;5;124;43m'[39;49m[43m,[49m[38;5;124;43m'[39;49m[38;5;124;43mabstract[39;49m[38;5;124;43m'[39;49m[43m][49m[43m)[49m
[1;32m      4[0m [38;5;28mprint[39m(df[38;5;241m.[39mshape)
[1;32m      6[0m df [38;5;241m=[39m get_categories(model_name, [38;5;124m'[39m[38;5;124m4 -[39m[38;5;124m'[39m, seen_df, df)

[0;31mTypeError[0m: DataFrame.dropna() takes 1 positional argument but 2 were given

